(dp1
S'output'
p2
S'<type \'exceptions.RuntimeError\'> Failure to connect, tried 5 times:\nTraceback (most recent call last):\n  File "C:\\Users\\hd\\PycharmProjects\\untitled\\web2py\\gluon\\packages\\dal\\pydal\\base.py", line 454, in __init__\n    self._adapter = adapter(**kwargs)\n  File "C:\\Users\\hd\\PycharmProjects\\untitled\\web2py\\gluon\\packages\\dal\\pydal\\adapters\\__init__.py", line 40, in __call__\n    obj = super(AdapterMeta, cls).__call__(*args, **kwargs)\n  File "C:\\Users\\hd\\PycharmProjects\\untitled\\web2py\\gluon\\packages\\dal\\pydal\\adapters\\base.py", line 368, in __init__\n    super(SQLAdapter, self).__init__(*args, **kwargs)\n  File "C:\\Users\\hd\\PycharmProjects\\untitled\\web2py\\gluon\\packages\\dal\\pydal\\adapters\\base.py", line 52, in __init__\n    self.reconnect()\n  File "C:\\Users\\hd\\PycharmProjects\\untitled\\web2py\\gluon\\packages\\dal\\pydal\\connection.py", line 172, in reconnect\n    self.connection = self.connector()\n  File "C:\\Users\\hd\\PycharmProjects\\untitled\\web2py\\gluon\\packages\\dal\\pydal\\adapters\\mysql.py", line 52, in connector\n    return self.driver.connect(**self.driver_args)\n  File "C:\\Users\\hd\\AppData\\Roaming\\Python\\Python27\\site-packages\\pymysql\\__init__.py", line 90, in Connect\n    return Connection(*args, **kwargs)\n  File "C:\\Users\\hd\\AppData\\Roaming\\Python\\Python27\\site-packages\\pymysql\\connections.py", line 699, in __init__\n    self.connect()\n  File "C:\\Users\\hd\\AppData\\Roaming\\Python\\Python27\\site-packages\\pymysql\\connections.py", line 967, in connect\n    raise exc\nOperationalError: (2003, "Can\'t connect to MySQL server on \'localhost\' ([Errno 10061] No connection could be made because the target machine actively refused it)")\n'
p3
sS'layer'
p4
S'C:\\Users\\hd\\PycharmProjects\\untitled\\web2py\\applications\\darkcloud1\\models\\db.py'
p5
sS'code'
p6
S'<code object <module> at 0000000008179C30, file "C:\\Users\\hd\\PycharmProjects\\untitled\\web2py\\applications\\darkcloud1\\models\\db.py", line 7>'
p7
sS'snapshot'
p8
(dp9
sS'traceback'
p10
S'Traceback (most recent call last):\n  File "C:\\Users\\hd\\PycharmProjects\\untitled\\web2py\\gluon\\restricted.py", line 219, in restricted\n    exec(ccode, environment)\n  File "C:\\Users\\hd\\PycharmProjects\\untitled\\web2py\\applications\\darkcloud1\\models\\db.py", line 39, in <module>\n    db = DAL(\'mysql://root:1@localhost/darkcloud\', pool_size=1, check_reserved=[\'all\'])\n  File "C:\\Users\\hd\\PycharmProjects\\untitled\\web2py\\gluon\\packages\\dal\\pydal\\base.py", line 169, in __call__\n    obj = super(MetaDAL, cls).__call__(*args, **kwargs)\n  File "C:\\Users\\hd\\PycharmProjects\\untitled\\web2py\\gluon\\packages\\dal\\pydal\\base.py", line 474, in __init__\n    "Failure to connect, tried %d times:\\n%s" % (attempts, tb)\nRuntimeError: Failure to connect, tried 5 times:\nTraceback (most recent call last):\n  File "C:\\Users\\hd\\PycharmProjects\\untitled\\web2py\\gluon\\packages\\dal\\pydal\\base.py", line 454, in __init__\n    self._adapter = adapter(**kwargs)\n  File "C:\\Users\\hd\\PycharmProjects\\untitled\\web2py\\gluon\\packages\\dal\\pydal\\adapters\\__init__.py", line 40, in __call__\n    obj = super(AdapterMeta, cls).__call__(*args, **kwargs)\n  File "C:\\Users\\hd\\PycharmProjects\\untitled\\web2py\\gluon\\packages\\dal\\pydal\\adapters\\base.py", line 368, in __init__\n    super(SQLAdapter, self).__init__(*args, **kwargs)\n  File "C:\\Users\\hd\\PycharmProjects\\untitled\\web2py\\gluon\\packages\\dal\\pydal\\adapters\\base.py", line 52, in __init__\n    self.reconnect()\n  File "C:\\Users\\hd\\PycharmProjects\\untitled\\web2py\\gluon\\packages\\dal\\pydal\\connection.py", line 172, in reconnect\n    self.connection = self.connector()\n  File "C:\\Users\\hd\\PycharmProjects\\untitled\\web2py\\gluon\\packages\\dal\\pydal\\adapters\\mysql.py", line 52, in connector\n    return self.driver.connect(**self.driver_args)\n  File "C:\\Users\\hd\\AppData\\Roaming\\Python\\Python27\\site-packages\\pymysql\\__init__.py", line 90, in Connect\n    return Connection(*args, **kwargs)\n  File "C:\\Users\\hd\\AppData\\Roaming\\Python\\Python27\\site-packages\\pymysql\\connections.py", line 699, in __init__\n    self.connect()\n  File "C:\\Users\\hd\\AppData\\Roaming\\Python\\Python27\\site-packages\\pymysql\\connections.py", line 967, in connect\n    raise exc\nOperationalError: (2003, "Can\'t connect to MySQL server on \'localhost\' ([Errno 10061] No connection could be made because the target machine actively refused it)")\n\n'
p11
s.